[2025-09-25T09:30:07.451+0000] {local_task_job_runner.py:120} INFO - ::group::Pre task execution logs
[2025-09-25T09:30:07.487+0000] {taskinstance.py:2076} INFO - Dependencies all met for dep_context=non-requeueable deps ti=<TaskInstance: weather_pipeline_orchestration.check_hdfs_health scheduled__2025-09-25T09:15:00+00:00 [queued]>
[2025-09-25T09:30:07.502+0000] {taskinstance.py:2076} INFO - Dependencies all met for dep_context=requeueable deps ti=<TaskInstance: weather_pipeline_orchestration.check_hdfs_health scheduled__2025-09-25T09:15:00+00:00 [queued]>
[2025-09-25T09:30:07.502+0000] {taskinstance.py:2306} INFO - Starting attempt 1 of 2
[2025-09-25T09:30:07.515+0000] {taskinstance.py:2330} INFO - Executing <Task(PythonOperator): check_hdfs_health> on 2025-09-25 09:15:00+00:00
[2025-09-25T09:30:07.564+0000] {standard_task_runner.py:90} INFO - Running: ['***', 'tasks', 'run', 'weather_pipeline_orchestration', 'check_hdfs_health', 'scheduled__2025-09-25T09:15:00+00:00', '--job-id', '34', '--raw', '--subdir', 'DAGS_FOLDER/weather_pipeline_orchestration.py', '--cfg-path', '/tmp/tmpx6itooml']
[2025-09-25T09:30:07.557+0000] {logging_mixin.py:188} WARNING - /home/***/.local/lib/python3.12/site-packages/***/task/task_runner/standard_task_runner.py:62 DeprecationWarning: This process (pid=961) is multi-threaded, use of fork() may lead to deadlocks in the child.
[2025-09-25T09:30:07.567+0000] {standard_task_runner.py:91} INFO - Job 34: Subtask check_hdfs_health
[2025-09-25T09:30:07.567+0000] {standard_task_runner.py:64} INFO - Started process 965 to run task
[2025-09-25T09:30:07.684+0000] {task_command.py:426} INFO - Running <TaskInstance: weather_pipeline_orchestration.check_hdfs_health scheduled__2025-09-25T09:15:00+00:00 [running]> on host 32ce42b7fa38
[2025-09-25T09:30:07.794+0000] {taskinstance.py:2648} INFO - Exporting env vars: AIRFLOW_CTX_DAG_OWNER='***' AIRFLOW_CTX_DAG_ID='weather_pipeline_orchestration' AIRFLOW_CTX_TASK_ID='check_hdfs_health' AIRFLOW_CTX_EXECUTION_DATE='2025-09-25T09:15:00+00:00' AIRFLOW_CTX_TRY_NUMBER='1' AIRFLOW_CTX_DAG_RUN_ID='scheduled__2025-09-25T09:15:00+00:00'
[2025-09-25T09:30:07.798+0000] {taskinstance.py:430} INFO - ::endgroup::
[2025-09-25T09:30:07.872+0000] {logging_mixin.py:188} INFO - ‚ùå HDFS health check failed: HTTPConnectionPool(host='namenode', port=9870): Max retries exceeded with url: / (Caused by NameResolutionError("<urllib3.connection.HTTPConnection object at 0xffffabc4cc50>: Failed to resolve 'namenode' ([Errno -2] Name or service not known)"))
[2025-09-25T09:30:07.872+0000] {taskinstance.py:441} INFO - ::group::Post task execution logs
[2025-09-25T09:30:07.873+0000] {taskinstance.py:2905} ERROR - Task failed with exception
Traceback (most recent call last):
  File "/home/airflow/.local/lib/python3.12/site-packages/urllib3/connection.py", line 203, in _new_conn
    sock = connection.create_connection(
           ^^^^^^^^^^^^^^^^^^^^^^^^^^^^^
  File "/home/airflow/.local/lib/python3.12/site-packages/urllib3/util/connection.py", line 60, in create_connection
    for res in socket.getaddrinfo(host, port, family, socket.SOCK_STREAM):
               ^^^^^^^^^^^^^^^^^^^^^^^^^^^^^^^^^^^^^^^^^^^^^^^^^^^^^^^^^^
  File "/usr/local/lib/python3.12/socket.py", line 964, in getaddrinfo
    for res in _socket.getaddrinfo(host, port, family, type, proto, flags):
               ^^^^^^^^^^^^^^^^^^^^^^^^^^^^^^^^^^^^^^^^^^^^^^^^^^^^^^^^^^^
socket.gaierror: [Errno -2] Name or service not known

The above exception was the direct cause of the following exception:

Traceback (most recent call last):
  File "/home/airflow/.local/lib/python3.12/site-packages/urllib3/connectionpool.py", line 791, in urlopen
    response = self._make_request(
               ^^^^^^^^^^^^^^^^^^^
  File "/home/airflow/.local/lib/python3.12/site-packages/urllib3/connectionpool.py", line 497, in _make_request
    conn.request(
  File "/home/airflow/.local/lib/python3.12/site-packages/urllib3/connection.py", line 395, in request
    self.endheaders()
  File "/usr/local/lib/python3.12/http/client.py", line 1331, in endheaders
    self._send_output(message_body, encode_chunked=encode_chunked)
  File "/usr/local/lib/python3.12/http/client.py", line 1091, in _send_output
    self.send(msg)
  File "/usr/local/lib/python3.12/http/client.py", line 1035, in send
    self.connect()
  File "/home/airflow/.local/lib/python3.12/site-packages/urllib3/connection.py", line 243, in connect
    self.sock = self._new_conn()
                ^^^^^^^^^^^^^^^^
  File "/home/airflow/.local/lib/python3.12/site-packages/urllib3/connection.py", line 210, in _new_conn
    raise NameResolutionError(self.host, self, e) from e
urllib3.exceptions.NameResolutionError: <urllib3.connection.HTTPConnection object at 0xffffabc4cc50>: Failed to resolve 'namenode' ([Errno -2] Name or service not known)

The above exception was the direct cause of the following exception:

Traceback (most recent call last):
  File "/home/airflow/.local/lib/python3.12/site-packages/requests/adapters.py", line 667, in send
    resp = conn.urlopen(
           ^^^^^^^^^^^^^
  File "/home/airflow/.local/lib/python3.12/site-packages/urllib3/connectionpool.py", line 845, in urlopen
    retries = retries.increment(
              ^^^^^^^^^^^^^^^^^^
  File "/home/airflow/.local/lib/python3.12/site-packages/urllib3/util/retry.py", line 515, in increment
    raise MaxRetryError(_pool, url, reason) from reason  # type: ignore[arg-type]
    ^^^^^^^^^^^^^^^^^^^^^^^^^^^^^^^^^^^^^^^^^^^^^^^^^^^
urllib3.exceptions.MaxRetryError: HTTPConnectionPool(host='namenode', port=9870): Max retries exceeded with url: / (Caused by NameResolutionError("<urllib3.connection.HTTPConnection object at 0xffffabc4cc50>: Failed to resolve 'namenode' ([Errno -2] Name or service not known)"))

During handling of the above exception, another exception occurred:

Traceback (most recent call last):
  File "/home/airflow/.local/lib/python3.12/site-packages/airflow/models/taskinstance.py", line 465, in _execute_task
    result = _execute_callable(context=context, **execute_callable_kwargs)
             ^^^^^^^^^^^^^^^^^^^^^^^^^^^^^^^^^^^^^^^^^^^^^^^^^^^^^^^^^^^^^
  File "/home/airflow/.local/lib/python3.12/site-packages/airflow/models/taskinstance.py", line 432, in _execute_callable
    return execute_callable(context=context, **execute_callable_kwargs)
           ^^^^^^^^^^^^^^^^^^^^^^^^^^^^^^^^^^^^^^^^^^^^^^^^^^^^^^^^^^^^
  File "/home/airflow/.local/lib/python3.12/site-packages/airflow/models/baseoperator.py", line 401, in wrapper
    return func(self, *args, **kwargs)
           ^^^^^^^^^^^^^^^^^^^^^^^^^^^
  File "/home/airflow/.local/lib/python3.12/site-packages/airflow/operators/python.py", line 235, in execute
    return_value = self.execute_callable()
                   ^^^^^^^^^^^^^^^^^^^^^^^
  File "/home/airflow/.local/lib/python3.12/site-packages/airflow/operators/python.py", line 252, in execute_callable
    return self.python_callable(*self.op_args, **self.op_kwargs)
           ^^^^^^^^^^^^^^^^^^^^^^^^^^^^^^^^^^^^^^^^^^^^^^^^^^^^^
  File "/opt/airflow/dags/weather_pipeline_orchestration.py", line 26, in check_hdfs_health
    response = requests.get("http://namenode:9870/", timeout=5)
               ^^^^^^^^^^^^^^^^^^^^^^^^^^^^^^^^^^^^^^^^^^^^^^^^
  File "/home/airflow/.local/lib/python3.12/site-packages/requests/api.py", line 73, in get
    return request("get", url, params=params, **kwargs)
           ^^^^^^^^^^^^^^^^^^^^^^^^^^^^^^^^^^^^^^^^^^^^
  File "/home/airflow/.local/lib/python3.12/site-packages/requests/api.py", line 59, in request
    return session.request(method=method, url=url, **kwargs)
           ^^^^^^^^^^^^^^^^^^^^^^^^^^^^^^^^^^^^^^^^^^^^^^^^^
  File "/home/airflow/.local/lib/python3.12/site-packages/requests/sessions.py", line 589, in request
    resp = self.send(prep, **send_kwargs)
           ^^^^^^^^^^^^^^^^^^^^^^^^^^^^^^
  File "/home/airflow/.local/lib/python3.12/site-packages/requests/sessions.py", line 703, in send
    r = adapter.send(request, **kwargs)
        ^^^^^^^^^^^^^^^^^^^^^^^^^^^^^^^
  File "/home/airflow/.local/lib/python3.12/site-packages/requests/adapters.py", line 700, in send
    raise ConnectionError(e, request=request)
requests.exceptions.ConnectionError: HTTPConnectionPool(host='namenode', port=9870): Max retries exceeded with url: / (Caused by NameResolutionError("<urllib3.connection.HTTPConnection object at 0xffffabc4cc50>: Failed to resolve 'namenode' ([Errno -2] Name or service not known)"))
[2025-09-25T09:30:07.887+0000] {taskinstance.py:1206} INFO - Marking task as UP_FOR_RETRY. dag_id=weather_pipeline_orchestration, task_id=check_hdfs_health, run_id=scheduled__2025-09-25T09:15:00+00:00, execution_date=20250925T091500, start_date=20250925T093007, end_date=20250925T093007
[2025-09-25T09:30:07.895+0000] {standard_task_runner.py:110} ERROR - Failed to execute job 34 for task check_hdfs_health (HTTPConnectionPool(host='namenode', port=9870): Max retries exceeded with url: / (Caused by NameResolutionError("<urllib3.connection.HTTPConnection object at 0xffffabc4cc50>: Failed to resolve 'namenode' ([Errno -2] Name or service not known)")); 965)
[2025-09-25T09:30:07.928+0000] {local_task_job_runner.py:243} INFO - Task exited with return code 1
[2025-09-25T09:30:07.942+0000] {taskinstance.py:3503} INFO - 0 downstream tasks scheduled from follow-on schedule check
[2025-09-25T09:30:07.944+0000] {local_task_job_runner.py:222} INFO - ::endgroup::
